Workbook

Sheet  List
J1: CORTE Y MECANIZADO DE HINCAS
C5: DATOS DE PROYECTO
C7: Proyecto: | D7: ISFV ATALAYA
C9: Población: | D9: VILLENA
C10: Provincia: | D10: ALICANTE
C13: MEDIDAS
C15: PV | D15: Nº TRACKER | E15: Nº DE HINCA | F15: FILA | G15: ALTURA HINCA (ANTES DEL CORTE) (mm) | H15: CORTE (mm) | I15: ALTURA TRAS EL CORTE (mm) | J15: LONGITUD NOMINAL PERFIL (mm) | K15: PROFUNDIDAD ALCANZADA HINCADO (mm) | L15: PROFUNDIDAD NOMINAL (mm) | M15: % HINCADO
C16: 14/2 | D16: 3 | E16: 4n | F16: Motora | G16: 1220 | J16: 3255 | K16: =+J16-G16 -> 2035 | L16: 1800 | M16: =+K16/L16 -> 1.1305556
C17: 14/2 | D17: 3 | E17: 3n | F17: Motora | G17: 1095 | J17: 3255 | K17: =+J17-G17 -> 2160 | L17: 1800 | M17: =+K17/L17 -> 1.2
C18: 14/2 | D18: 3 | E18: 2n | F18: Motora | G18: 1140 | J18: 3255 | K18: =+J18-G18 -> 2115 | L18: 1800 | M18: =+K18/L18 -> 1.175
C19: 14/2 | D19: 3 | E19: 1n | F19: Motora | G19: 1125 | J19: 3255 | K19: =+J19-G19 -> 2130 | L19: 1800 | M19: =+K19/L19 -> 1.1833333
C20: 14/2 | D20: 3 | E20: MP | F20: Motora | G20: 1135 | J20: 3280 | K20: =+J20-G20 -> 2145 | L20: 1800 | M20: =+K20/L20 -> 1.1916667
C21: 14/2 | D21: 3 | E21: 1S | F21: Motora | G21: 1110 | J21: 3255 | K21: =+J21-G21 -> 2145 | L21: 1800 | M21: =+K21/L21 -> 1.1916667
C22: 14/2 | D22: 3 | E22: 2S | F22: Motora | G22: 1120 | J22: 3255 | K22: =+J22-G22 -> 2135 | L22: 1800 | M22: =+K22/L22 -> 1.1861111
C23: 14/2 | D23: 3 | E23: 3S | F23: Motora | G23: 1200 | J23: 3255 | K23: =+J23-G23 -> 2055 | L23: 1800 | M23: =+K23/L23 -> 1.1416667
C24: 14/2 | D24: 3 | E24: 4S | F24: Motora | G24: 1225 | J24: 3255 | K24: =+J24-G24 -> 2030 | L24: 1800 | M24: =+K24/L24 -> 1.1277778
C25: 14/2 | D25: 6 | E25: 4n | F25: Motora | G25: 1245 | J25: 3255 | K25: =+J25-G25 -> 2010 | L25: 1800 | M25: =+K25/L25 -> 1.1166667
C26: 14/2 | D26: 6 | E26: 3n | F26: Motora | G26: 1220 | J26: 3255 | K26: =+J26-G26 -> 2035 | L26: 1800 | M26: =+K26/L26 -> 1.1305556
C27: 14/2 | D27: 6 | E27: 2n | F27: Motora | G27: 1200 | J27: 3255 | K27: =+J27-G27 -> 2055 | L27: 1800 | M27: =+K27/L27 -> 1.1416667
... C240: 14/2 | D240: 38 | E240: 4s | F240: Conducida | G240: 1255 | J240: 3255 | K240: =+J240-G240 -> 2000 | L240: 1800 | M240: =+K240/L240 -> 1.1111111
C241: 14/2 | D241: 41 | E241: 4n | F241: Motora | J241: 3255 | K241: =+J241-G241 -> 3255 | L241: 1800 | M241: =+K241/L241 -> 1.8083333
C242: 14/2 | D242: 41 | E242: 3n | F242: Motora | J242: 3255 | K242: =+J242-G242 -> 3255 | L242: 1800 | M242: =+K242/L242 -> 1.8083333
C243: 14/2 | D243: 41 | E243: 2n | F243: Motora | J243: 3255 | K243: =+J243-G243 -> 3255 | L243: 1800 | M243: =+K243/L243 -> 1.8083333
C244: 14/2 | D244: 41 | E244: 1n | F244: Motora | J244: 3255 | K244: =+J244-G244 -> 3255 | L244: 1800 | M244: =+K244/L244 -> 1.8083333
C245: 14/2 | D245: 41 | E245: MP | F245: Motora | J245: 3280 | K245: =+J245-G245 -> 3280 | L245: 1800 | M245: =+K245/L245 -> 1.8222222
C246: 14/2 | D246: 41 | E246: 1s | F246: Motora | J246: 3255 | K246: =+J246-G246 -> 3255 | L246: 1800 | M246: =+K246/L246 -> 1.8083333
C247: 14/2 | D247: 41 | E247: 2s | F247: Motora | J247: 3255 | K247: =+J247-G247 -> 3255 | L247: 1800 | M247: =+K247/L247 -> 1.8083333
C248: 14/2 | D248: 41 | E248: 3s | F248: Motora | J248: 3255 | K248: =+J248-G248 -> 3255 | L248: 1800 | M248: =+K248/L248 -> 1.8083333
C249: 14/2 | D249: 41 | E249: 4s | F249: Motora | J249: 3255 | K249: =+J249-G249 -> 3255 | L249: 1800 | M249: =+K249/L249 -> 1.8083333
C250: 14/2 | D250: 41 | E250: MP-FC | F250: Conducida | J250: 3280 | K250: =+J250-G250 -> 3280 | L250: 1800 | M250: =+K250/L250 -> 1.8222222
C251: 14/2 | D251: 41 | E251: 4n | F251: Conducida | J251: 3255 | K251: =+J251-G251 -> 3255 | L251: 1800 | M251: =+K251/L251 -> 1.8083333
C252: 14/2 | D252: 41 | E252: 3n | F252: Conducida | H252: 190 | I252: =+G252-H252 -> -190 | J252: 3255 | K252: =+J252-G252 -> 3255 | L252: 1800 | M252: =+K252/L252 -> 1.8083333
C253: 14/2 | D253: 41 | E253: 2n | F253: Conducida | J253: 3255 | K253: =+J253-G253 -> 3255 | L253: 1800 | M253: =+K253/L253 -> 1.8083333
C254: 14/2 | D254: 41 | E254: 1n | F254: Conducida | J254: 3255 | K254: =+J254-G254 -> 3255 | L254: 1800 | M254: =+K254/L254 -> 1.8083333
C255: 14/2 | D255: 41 | E255: 1s | F255: Conducida | J255: 3255 | K255: =+J255-G255 -> 3255 | L255: 1800 | M255: =+K255/L255 -> 1.8083333
C256: 14/2 | D256: 41 | E256: 2s | F256: Conducida | J256: 3255 | K256: =+J256-G256 -> 3255 | L256: 1800 | M256: =+K256/L256 -> 1.8083333
C257: 14/2 | D257: 41 | E257: 3s | F257: Conducida | J257: 3255 | K257: =+J257-G257 -> 3255 | L257: 1800 | M257: =+K257/L257 -> 1.8083333
C258: 14/2 | D258: 41 | E258: 4s | F258: Conducida | J258: 3255 | K258: =+J258-G258 -> 3255 | L258: 1800 | M258: =+K258/L258 -> 1.8083333
C259: 14/2 | D259: 44 | E259: 4n | F259: Motora | H259: 310 | I259: =+G259-H259 -> -310 | J259: 3255 | K259: =+J259-G259 -> 3255 | L259: 1800 | M259: =+K259/L259 -> 1.8083333
C260: 14/2 | D260: 44 | E260: 3n | F260: Motora | J260: 3255 | K260: =+J260-G260 -> 3255 | L260: 1800 | M260: =+K260/L260 -> 1.8083333
...

Sheet Informes POT
A1: DATOS
A2: Tipo POT (Validación o Rechazo) | C2: Validación | D2: Fecha | E2: 46057 | F2: Condiciones de terreno | H2: Seco
A3: Posición perfil (Expuesto o Resguardo) | C3: Resguardo | D3: Tipo de perfil | E3: C150 | G3: Hinca | H3: FC-4N
A4: Zona | B4: PV14-2 | C4: Nº de Tracker | D4: 9 | E4: Altura de hinca (mm) | F4: 1240 | G4: Altura de apliación (mm) | H4: 1000
A5: RESULTADOS
A6: ENSAYO | B6: CARGA | C6: TEÓRICO (KN) | D6: TEÓRICO (Kg) | E6: REAL (KN) | F6: REAL (Kg) | G6: DESPLAZ. (mm) | H6: RESULTADO (OK/NO OK) | I6: TOLERANCIA (mm)
A7: TRACCIÓN | B7: M1 ELUtracción x0,50 | C7: =+D7/100 -> 5.1 | D7: 510 | E7: =+F7/100 -> 5.4 | F7: 540 | G7: 0.06 | H7: =+IF(G7<5,"OK","NOK") -> OK | I7: <5
B8: M2 ELUtracción x0,70 | C8: =+D8/100 -> 7.6 | D8: 760 | E8: =+F8/100 -> 7.84 | F8: 784 | G8: 0.1 | H8: =+IF(G8<10,"OK","NOK") -> OK | I8: <10
A9: CORTANTE | B9: M1 ELUtracción x0,50 | C9: =+D9/100 -> 3.26 | D9: 326 | E9: =+F9/100 -> 3.38 | F9: 338 | G9: 6.06 | H9: =+IF(G9<10,"OK","NOK") -> OK | I9: <10
B10: M2 Descarga | C10: =+D10/100 -> 0 | D10: 0 | E10: =+F10/100 -> 0 | F10: 0 | G10: 2.08 | H10: =+IF(G10<5,"OK","NOK") -> OK | I10: <5
B11: M3 ELUtracción x0,70 | C11: =+D11/100 -> 4.48 | D11: 448 | E11: =+F11/100 -> 4.86 | F11: 486 | G11: 8.95 | H11: =+IF(G11<15,"OK","NOK") -> OK | I11: <15
B12: M4 Descarga | C12: =+D12/100 -> 0 | D12: 0 | E12: =+F12/100 -> 0 | F12: 0 | G12: 3.27 | H12: =+IF(G12<10,"OK","NOK") -> OK | I12: <10
A14: DATOS
A15: Tipo POT (Validación o Rechazo) | C15: Validación | D15: Fecha | E15: =+E2 -> 46057 | F15: Condiciones de terreno | H15: =+H2 -> Seco
A16: Posición perfil (Expuesto o Resguardo) | C16: Resguardo | D16: Tipo de perfil | E16: C150 | G16: Hinca | H16: FC-4S
A17: Zona | B17: =+B4 -> PV14-2 | C17: Nº de Tracker | D17: 23 | E17: Altura de hinca (mm) | F17: 1260 | G17: Altura de apliación (mm) | H17: =+H4 -> 1000
A18: RESULTADOS
A19: ENSAYO | B19: CARGA | C19: TEÓRICO (KN) | D19: TEÓRICO (Kg) | E19: REAL (KN) | F19: REAL (Kg) | G19: DESPLAZ. (mm) | H19: RESULTADO (OK/NO OK) | I19: TOLERANCIA (mm)
A20: TRACCIÓN | B20: M1 ELUtracción x0,50 | C20: =+D20/100 -> 5.1 | D20: 510 | E20: =+F20/100 -> 5.3 | F20: 530 | G20: 0.34 | H20: =+IF(G20<5,"OK","NOK") -> OK | I20: <5
B21: M2 ELUtracción x0,70 | C21: =+D21/100 -> 7.6 | D21: =+D8 -> 760 | E21: =+F21/100 -> 8 | F21: 800 | G21: 0.58 | H21: =+IF(G21<10,"OK","NOK") -> OK | I21: <10
A22: CORTANTE | B22: M1 ELUtracción x0,50 | C22: =+D22/100 -> 3.26 | D22: =+D9 -> 326 | E22: =+F22/100 -> 3.46 | F22: 346 | G22: 4.8 | H22: =+IF(G22<10,"OK","NOK") -> OK | I22: <10
B23: M2 Descarga | C23: =+D23/100 -> 0 | D23: =+D10 -> 0 | E23: =+F23/100 -> 0 | F23: 0 | G23: 1.2 | H23: =+IF(G23<5,"OK","NOK") -> OK | I23: <5
B24: M3 ELUtracción x0,70 | C24: =+D24/100 -> 4.48 | D24: =+D11 -> 448 | E24: =+F24/100 -> 4.62 | F24: 462 | G24: 6.8 | H24: =+IF(G24<15,"OK","NOK") -> OK | I24: <15
B25: M4 Descarga | C25: =+D25/100 -> 0 | D25: =+D12 -> 0 | E25: =+F25/100 -> 0 | F25: 0 | G25: 1.55 | H25: =+IF(G25<10,"OK","NOK") -> OK | I25: <10
A27: DATOS
A28: Tipo POT (Validación o Rechazo) | C28: Validación | D28: Fecha | E28: =+E15 -> 46057 | F28: Condiciones de terreno | H28: =+H15 -> Seco
A29: Posición perfil (Expuesto o Resguardo) | C29: Resguardo | D29: Tipo de perfil | E29: W6 | G29: Hinca | H29: FM-M
A30: Zona | B30: =+B17 -> PV14-2 | C30: Nº de Tracker | D30: 35 | E30: Altura de hinca (mm) | F30: 1310 | G30: Altura de apliación (mm) | H30: =+H17 -> 1000
A31: RESULTADOS
A32: ENSAYO | B32: CARGA | C32: TEÓRICO (KN) | D32: TEÓRICO (Kg) | E32: REAL (KN) | F32: REAL (Kg) | G32: DESPLAZ. (mm) | H32: RESULTADO (OK/NO OK) | I32: TOLERANCIA (mm)
A33: TRACCIÓN | B33: M1 ELUtracción x0,50 | C33: =+D33/100 -> 5.1 | D33: =+D20 -> 510 | E33: =+F33/100 -> 5.42 | F33: 542 | G33: 0.11 | H33: =+IF(G33<5,"OK","NOK") -> OK | I33: <5
B34: M2 ELUtracción x0,70 | C34: =+D34/100 -> 7.6 | D34: =+D21 -> 760 | E34: =+F34/100 -> 7.92 | F34: 792 | G34: 0.31 | H34: =+IF(G34<10,"OK","NOK") -> OK | I34: <10
A35: CORTANTE | B35: M1 ELUtracción x0,50 | C35: =+D35/100 -> 6.63 | D35: 663 | E35: =+F35/100 -> 6.76 | F35: 676 | G35: 4.09 | H35: =+IF(G35<10,"OK","NOK") -> OK | I35: <10
B36: M2 Descarga | C36: =+D36/100 -> 0 | D36: =+D23 -> 0 | E36: =+F36/100 -> 0 | F36: 0 | G36: 1.36 | H36: =+IF(G36<5,"OK","NOK") -> OK | I36: <5
B37: M3 ELUtracción x0,70 | C37: =+D37/100 -> 9.18 | D37: 918 | E37: =+F37/100 -> 9.38 | F37: 938 | G37: 6.47 | H37: =+IF(G37<15,"OK","NOK") -> OK | I37: <15
B38: M4 Descarga | C38: =+D38/100 -> 0 | D38: =+D25 -> 0 | E38: =+F38/100 -> 0 | F38: 0 | G38: 1.94 | H38: =+IF(G38<10,"OK","NOK") -> OK | I38: <10
A40: DATOS
A41: Tipo POT (Validación o Rechazo) | D41: Fecha | E41: =+E28 -> 46057 | F41: Condiciones de terreno
A42: Posición perfil (Expuesto o Resguardo) | D42: Tipo de perfil | G42: Hinca
A43: Zona | B43: =+B30 -> PV14-2 | C43: Nº de Tracker | E43: Altura de hinca (mm) | G43: Altura de apliación (mm)
...

Sheet Reporte Fotográfico
A1: =+CONCATENATE('Informes POT'!D4,"-",'Informes POT'!H3) -> 9-FC-4N | B1: #VALUE! | C1: #VALUE! | D1: #VALUE!
A2: =+CONCATENATE('Informes POT'!D17,"-",'Informes POT'!H16) -> 23-FC-4S | B2: #VALUE! | C2: #VALUE! | D2: #VALUE!
A3: =+CONCATENATE('Informes POT'!D30,"-",'Informes POT'!H29) -> 35-FM-M | B3: #VALUE! | C3: #VALUE! | D3: #VALUE!
A4: =+CONCATENATE('Informes POT'!D43,"-",'Informes POT'!H42) -> -
A5: =+CONCATENATE('Informes POT'!D56,"-",'Informes POT'!H55) -> -
A6: =+CONCATENATE('Informes POT'!D69,"-",'Informes POT'!H68) -> -
